バグを含むソースコードに対して実行した場合の実行結果出力
Traceback (most recent call last):
  File "/usr/local/Cellar/python/3.6.5/Frameworks/Python.framework/Versions/3.6/lib/python3.6/runpy.py", line 193, in _run_module_as_main
    "__main__", mod_spec)
  File "/usr/local/Cellar/python/3.6.5/Frameworks/Python.framework/Versions/3.6/lib/python3.6/runpy.py", line 85, in _run_code
    exec(code, run_globals)
  File "/usr/local/Cellar/python/3.6.5/Frameworks/Python.framework/Versions/3.6/lib/python3.6/unittest/__main__.py", line 18, in <module>
    main(module=None)
  File "/usr/local/Cellar/python/3.6.5/Frameworks/Python.framework/Versions/3.6/lib/python3.6/unittest/main.py", line 94, in __init__
    self.parseArgs(argv)
  File "/usr/local/Cellar/python/3.6.5/Frameworks/Python.framework/Versions/3.6/lib/python3.6/unittest/main.py", line 141, in parseArgs
    self.createTests()
  File "/usr/local/Cellar/python/3.6.5/Frameworks/Python.framework/Versions/3.6/lib/python3.6/unittest/main.py", line 148, in createTests
    self.module)
  File "/usr/local/Cellar/python/3.6.5/Frameworks/Python.framework/Versions/3.6/lib/python3.6/unittest/loader.py", line 219, in loadTestsFromNames
    suites = [self.loadTestsFromName(name, module) for name in names]
  File "/usr/local/Cellar/python/3.6.5/Frameworks/Python.framework/Versions/3.6/lib/python3.6/unittest/loader.py", line 219, in <listcomp>
    suites = [self.loadTestsFromName(name, module) for name in names]
  File "/usr/local/Cellar/python/3.6.5/Frameworks/Python.framework/Versions/3.6/lib/python3.6/unittest/loader.py", line 153, in loadTestsFromName
    module = __import__(module_name)
  File "/Users/kondoshogo/PycharmProjects/untitled8/test_Procon.py", line 2, in <module>
    import procon
  File "/Users/kondoshogo/PycharmProjects/untitled8/procon.py", line 31
    if d ==  and s[i] == True:
               ^
SyntaxError: invalid syntax

バグのないソースコードに対して実行した場合の実行結果出力
5
.1
.4800
.6
.
----------------------------------------------------------------------
Ran 4 tests in 0.034s

OK
